[2022-07-14 07:01:12,730] {taskinstance.py:1173} INFO - Dependencies not met for <TaskInstance: project_dag_v3.print_data scheduled__2022-07-13T00:00:00+00:00 [up_for_retry]>, dependency 'Not In Retry Period' FAILED: Task is not ready for retry yet but will be retried automatically. Current date is 2022-07-14T07:01:12.730544+00:00 and task will be retried at 2022-07-14T07:03:09.892426+00:00.
[2022-07-14 07:01:12,733] {local_task_job.py:101} INFO - Task is not able to be run
[2022-07-14 08:57:15,904] {taskinstance.py:1179} INFO - Dependencies all met for <TaskInstance: project_dag_v3.print_data scheduled__2022-07-13T00:00:00+00:00 [queued]>
[2022-07-14 08:57:15,936] {taskinstance.py:1179} INFO - Dependencies all met for <TaskInstance: project_dag_v3.print_data scheduled__2022-07-13T00:00:00+00:00 [queued]>
[2022-07-14 08:57:15,938] {taskinstance.py:1376} INFO - 
--------------------------------------------------------------------------------
[2022-07-14 08:57:15,939] {taskinstance.py:1377} INFO - Starting attempt 6 of 6
[2022-07-14 08:57:15,940] {taskinstance.py:1378} INFO - 
--------------------------------------------------------------------------------
[2022-07-14 08:57:15,995] {taskinstance.py:1397} INFO - Executing <Task(PythonOperator): print_data> on 2022-07-13 00:00:00+00:00
[2022-07-14 08:57:16,037] {standard_task_runner.py:52} INFO - Started process 9803 to run task
[2022-07-14 08:57:16,070] {standard_task_runner.py:79} INFO - Running: ['***', 'tasks', 'run', 'project_dag_v3', 'print_data', 'scheduled__2022-07-13T00:00:00+00:00', '--job-id', '99', '--raw', '--subdir', 'DAGS_FOLDER/project_dag.py', '--cfg-path', '/tmp/tmpanpz2zq4', '--error-file', '/tmp/tmpiijjhuiu']
[2022-07-14 08:57:16,117] {standard_task_runner.py:80} INFO - Job 99: Subtask print_data
[2022-07-14 08:57:16,343] {task_command.py:371} INFO - Running <TaskInstance: project_dag_v3.print_data scheduled__2022-07-13T00:00:00+00:00 [running]> on host 3bcedaf5b66b
[2022-07-14 08:57:16,590] {taskinstance.py:1591} INFO - Exporting the following env vars:
AIRFLOW_CTX_DAG_OWNER=harshab
AIRFLOW_CTX_DAG_ID=project_dag_v3
AIRFLOW_CTX_TASK_ID=print_data
AIRFLOW_CTX_EXECUTION_DATE=2022-07-13T00:00:00+00:00
AIRFLOW_CTX_TRY_NUMBER=6
AIRFLOW_CTX_DAG_RUN_ID=scheduled__2022-07-13T00:00:00+00:00
[2022-07-14 08:57:16,624] {taskinstance.py:1909} ERROR - Task failed with exception
Traceback (most recent call last):
  File "/home/airflow/.local/lib/python3.7/site-packages/airflow/operators/python.py", line 171, in execute
    return_value = self.execute_callable()
  File "/home/airflow/.local/lib/python3.7/site-packages/airflow/operators/python.py", line 189, in execute_callable
    return self.python_callable(*self.op_args, **self.op_kwargs)
  File "/opt/airflow/dags/project_dag.py", line 30, in print_data
    df = pd.read_csv(data_csv_file)
  File "/home/airflow/.local/lib/python3.7/site-packages/pandas/util/_decorators.py", line 311, in wrapper
    return func(*args, **kwargs)
  File "/home/airflow/.local/lib/python3.7/site-packages/pandas/io/parsers/readers.py", line 586, in read_csv
    return _read(filepath_or_buffer, kwds)
  File "/home/airflow/.local/lib/python3.7/site-packages/pandas/io/parsers/readers.py", line 482, in _read
    parser = TextFileReader(filepath_or_buffer, **kwds)
  File "/home/airflow/.local/lib/python3.7/site-packages/pandas/io/parsers/readers.py", line 811, in __init__
    self._engine = self._make_engine(self.engine)
  File "/home/airflow/.local/lib/python3.7/site-packages/pandas/io/parsers/readers.py", line 1040, in _make_engine
    return mapping[engine](self.f, **self.options)  # type: ignore[call-arg]
  File "/home/airflow/.local/lib/python3.7/site-packages/pandas/io/parsers/c_parser_wrapper.py", line 51, in __init__
    self._open_handles(src, kwds)
  File "/home/airflow/.local/lib/python3.7/site-packages/pandas/io/parsers/base_parser.py", line 229, in _open_handles
    errors=kwds.get("encoding_errors", "strict"),
  File "/home/airflow/.local/lib/python3.7/site-packages/pandas/io/common.py", line 614, in get_handle
    storage_options=storage_options,
  File "/home/airflow/.local/lib/python3.7/site-packages/pandas/io/common.py", line 396, in _get_filepath_or_buffer
    raise ValueError(msg)
ValueError: Invalid file path or buffer object type: <class 'NoneType'>
[2022-07-14 08:57:16,648] {taskinstance.py:1420} INFO - Marking task as FAILED. dag_id=project_dag_v3, task_id=print_data, execution_date=20220713T000000, start_date=20220714T085715, end_date=20220714T085716
[2022-07-14 08:57:16,677] {standard_task_runner.py:97} ERROR - Failed to execute job 99 for task print_data (Invalid file path or buffer object type: <class 'NoneType'>; 9803)
[2022-07-14 08:57:16,705] {local_task_job.py:156} INFO - Task exited with return code 1
[2022-07-14 08:57:16,901] {local_task_job.py:273} INFO - 0 downstream tasks scheduled from follow-on schedule check
